Workbook

Sheet Cover
A1: ILAM FAHARI I-REIT — LISTED REIT VALUATION MODEL
A2: NSE: FAHR | Kenya's Only Listed REIT | KES '000 unless stated
B4: REIT Name | C4: ILAM Fahari I-REIT
B5: Ticker | C5: NSE: FAHR
B6: Type | C6: Income REIT (I-REIT) — Commercial Real Estate
B7: Trustee | C7: Kenya Commercial Bank Nominees Limited
B8: REIT Manager | C8: ICEA Lion Asset Management (ILAM)
B9: Portfolio | C9: Greenspan Mall (Donholm), Bay Holdings (Mombasa Rd), 67 Gitanga Rd, Karen
B10: Units in Issue | C10: 180,541,176
B11: Market Price (KES) | C11: 6.00
B12: Market Cap (KES mn) | C12: ~1,083
B13: NAV per Unit (KES) | C13: 28.69
B14: NAV Discount | C14: (79.1%) — stock trades at 79% discount to NAV
B15: Currency | C15: Kenya Shillings (KES '000)
... B17: Valuation Methods | C17: NAV, DDM (Gordon Growth), DCF, Capitalisation Rate
A19: MODEL STRUCTURE
A20: 1 | B20: Cover | C20: Overview, REIT profile, tab index
A21: 2 | B21: Assumptions | C21: All key inputs: cap rate, growth, discount rate, occupancy
A22: 3 | B22: REIT Financials | C22: Income Statement, Balance Sheet, NAV Statement
A23: 4 | B23: NAV Valuation | C23: Net Asset Value per unit — primary REIT valuation metric
A24: 5 | B24: DDM Valuation | C24: Dividend Discount Model — Gordon Growth Model
A25: 6 | B25: DCF Valuation | C25: Discounted Cash Flow on Free Cash Flow to Equity
A26: 7 | B26: Cap Rate Analysis | C26: Capitalisation rate benchmarking and implied values
A27: 8 | B27: Sensitivity Analysis | C27: NAV, cap rate, DPU vs required yield tables
A28: 9 | B28: Summary | C28: Valuation bridge, recommendation, REIT investment thesis

Sheet Assumptions
A1: ASSUMPTIONS & KEY INPUTS — ILAM FAHARI I-REIT
A2: Blue = editable | Yellow = key assumption | Green = formula
A4: A. PROPERTY & INCOME ASSUMPTIONS
A5: Portfolio Fair Value (KES '000) | B5: 5680000 | C5: Source: Valuation Report 2024
A6: Market Cap Rate (Entry) | B6: 0.0572 | C6: NOI/Portfolio Value
A7: Target Cap Rate (Exit/Market) | B7: 0.08 | C7: Market normalisation assumption ← KEY
A8: Occupancy Rate (Current) | B8: 0.812 | C8: Portfolio weighted average
A9: Stabilised Occupancy (Target) | B9: 0.9 | C9: Sector norm for commercial RE
A10: Gross Rental Yield | B10: 0.083 | C10: Gross rental/portfolio value
A11: Rental Growth Rate pa (FY2025E) | B11: 0.04 | C11: CPI + modest real growth
A12: Long-term Rental Growth Rate | B12: 0.04 | C12: Terminal growth
A13: Property Cost Ratio (% of Revenue) | B13: 0.19 | C13: Maintenance + management
A14: Management Fee (% AUM) | B14: 0.0073 | C14: ~0.73% of portfolio value pa
A15: Finance Cost (% of Borrowings) | B15: 0.034 | C15: Cost of debt on borrowings
A16: Tax Rate | B16: 0 | C16: REITs are tax-exempt in Kenya
A17: Distribution Payout (% of Distributable Income) | B17: 0.8 | C17: Policy: min 80% required
A19: B. DISCOUNT RATE & WACC
A20: Risk-Free Rate (10-yr KE Treasury) | B20: 0.125 | C20: Kenya 10-yr sovereign
A21: Real Estate Risk Premium | B21: 0.035 | C21: Illiquidity + sector risk
A22: REIT-Specific Beta | B22: 0.7 | C22: Listed REIT — lower β than equities
A23: Required Return on Equity (REIT) | B23: =B20+B22*B21 -> 0.1495 | C23: =B23 -> 0.1495
A24: Cost of Debt (pre-tax) | B24: 0.134 | C24: KCB loan rate assumption
A25: Debt/Total Capital | B25: 0.112 | C25: Borrowings/(Borrowings+NAV)
A26: WACC | B26: =B23*(1-B25)+B24*(1-B16)*B25 -> 0.147764 | C26: Blended cost of capital
A27: Perpetuity Growth Rate (DDM/DCF) | B27: 0.04 | C27: Long-run rental growth
A29: C. MARKET DATA
A30: Units in Issue ('000) | B30: 180541 | C30: ILAM Fahari I-REIT AR 2024
A31: Current Market Price (KES) | B31: 6 | C31: NSE: FAHR
A32: Market Capitalisation (KES '000) | B32: =B30*B31 -> 1083246 | C32: =B32 -> 1083246
A33: Total Borrowings (KES '000) | B33: 650000 | C33: Balance Sheet
A34: Cash & Equivalents (KES '000) | B34: 142000 | C34: Balance Sheet
A35: Enterprise Value (KES '000) | B35: =B32+B33-B34 -> 1591246 | C35: =B35 -> 1591246

Sheet REIT Financials
A1: REIT FINANCIAL STATEMENTS — ILAM FAHARI I-REIT
A2: KES '000 | Source: ILAM Fahari I-REIT Annual Report 2024
A4: LINE ITEM | B4: FY2023 | C4: FY2024 | D4: YoY% | E4: % of Revenue
A5: INCOME STATEMENT
A6: Gross Rental Income | B6: 454200 | C6: 469374 | D6: =(C6-B6)/ABS(B6) -> 0.03340819
A7: Other Income | B7: 8100 | C7: 8500 | D7: =(C7-B7)/ABS(B7) -> 0.049382716
A8: Total Revenue | B8: 462300 | C8: 477874 | D8: =(C8-B8)/ABS(B8) -> 0.033688081 | E8: =C8/C8 -> 1
A9: Property Management Fee | B9: -40200 | C9: 41200 | D9: =(C9-B9)/ABS(B9) -> 2.0248756 | E9: =C9/C8 -> 0.086215195
A10: Property Costs & Rates | B10: -85600 | C10: 89400 | D10: =(C10-B10)/ABS(B10) -> 2.0443925 | E10: =C10/C8 -> 0.1870786
A11: Administration Costs | B11: -21100 | C11: 22300 | D11: =(C11-B11)/ABS(B11) -> 2.056872 | E11: =C11/C8 -> 0.04666502
A12: Total Operating Costs | B12: -146900 | C12: 152900 | D12: =(C12-B12)/ABS(B12) -> 2.0408441 | E12: =C12/C8 -> 0.31995882
A13: Net Operating Income (NOI) | B13: 308900 | C13: 324974 | D13: =(C13-B13)/ABS(B13) -> 0.052036258 | E13: =C13/C8 -> 0.68004118
A14: Finance Costs | B14: -17200 | C14: 18600 | D14: =(C14-B14)/ABS(B14) -> 2.0813953 | E14: =C14/C8 -> 0.038922394
A15: Profit Before Distribution | B15: 291700 | C15: 306374 | D15: =(C15-B15)/ABS(B15) -> 0.050305108 | E15: =C15/C8 -> 0.64111879
A16: Tax (Exempt for REIT) | B16: 0 | C16: 0 | E16: =C16/C8 -> 0
A17: Distributable Income | B17: 291700 | C17: 306374 | D17: =(C17-B17)/ABS(B17) -> 0.050305108 | E17: =C17/C8 -> 0.64111879
A18: Distributions Paid | B18: -223000 | C18: -225676 | D18: =(C18-B18)/ABS(B18) -> -0.012 | E18: =C18/C8 -> -0.47225001
A19: DPU (KES per unit) | B19: 1.2 | C19: 1.25 | D19: =(C19-B19)/ABS(B19) -> 0.041666667 | E19: =C19/C8 -> 2.6157523e-06
A21: BALANCE SHEET
A22: Investment Properties (Fair Value) | B22: 5720000 | C22: 5680000 | D22: =(C22-B22)/ABS(B22) -> -0.006993007 | E22: =C22/C8 -> 11.885978
A23: Cash & Cash Equivalents | B23: 138000 | C23: 142000 | D23: =(C23-B23)/ABS(B23) -> 0.028985507 | E23: =C23/C8 -> 0.29714946
A24: Other Assets | B24: 92000 | C24: 98400 | D24: =(C24-B24)/ABS(B24) -> 0.069565217 | E24: =C24/C8 -> 0.20591202
A25: Total Assets | B25: 5950000 | C25: 5920400 | D25: =(C25-B25)/ABS(B25) -> -0.0049747899 | E25: =C25/C8 -> 12.38904
A26: Borrowings | B26: 680000 | C26: 650000 | D26: =(C26-B26)/ABS(B26) -> -0.044117647 | E26: =C26/C8 -> 1.3601912
A27: Other Liabilities | B27: 92000 | C27: 89500 | D27: =(C27-B27)/ABS(B27) -> -0.027173913 | E27: =C27/C8 -> 0.18728786
A28: Total Liabilities | B28: 772000 | C28: 739500 | D28: =(C28-B28)/ABS(B28) -> -0.042098446 | E28: =C28/C8 -> 1.547479
A29: Net Asset Value (NAV) | B29: 5220000 | C29: 5180900 | D29: =(C29-B29)/ABS(B29) -> -0.0074904215 | E29: =C29/C8 -> 10.841561
A30: NAV per Unit (KES) | B30: 28.9131 | C30: 28.69 | D30: =(C30-B30)/ABS(B30) -> -0.007716228 | E30: =C30/C8 -> 6.0036746e-05
A32: KEY REIT METRICS
A33: Occupancy Rate | B33: 0.797 | C33: 0.812
A34: Capitalisation Rate (NOI/Value) | B34: 0.054 | C34: 0.0572
A35: Net Yield (NOI after costs/Value) | B35: 0.051 | C35: 0.0605
A36: Payout Ratio (Dist/Dist Income) | B36: 0.7645 | C36: 0.7366
A37: Loan-to-Value (LTV) | B37: 0.1189 | C37: 0.1144
A38: NAV Discount to Market | B38: -995.1911 | C38: -0.7909
A39: DPU Yield (DPU/Price) | B39: 0.2 | C39: 0.2083

Sheet NAV Valuation
A1: NET ASSET VALUE (NAV) VALUATION — PRIMARY REIT METRIC
A2: NAV = Total Assets - Total Liabilities | NAV/unit = intrinsic floor value for REITs
A4: A. DIRECT PROPERTY VALUATION (INCOME APPROACH)
A5: Item | B5: KES '000 | C5: Notes
A6: Greenspan Mall (Donholm) — Fair Value | B6: 2830000 | C6: Primary asset — 45,000 sqm GLA retail
A7: Bay Holdings (Mombasa Rd) — Fair Value | B7: 1680000 | C7: 26,000 sqm commercial office/retail
A8: 67 Gitanga Road Office Park — Fair Value | B8: 820000 | C8: 12,500 sqm commercial offices
A9: Karen Property — Fair Value | B9: 350000 | C9: Residential/mixed development
A10: Total Investment Property (Fair Value) | B10: =SUM(B6:B9) -> 5680000 | C10: Sum of above — CBRE valuation
A11: Cash & Short-term Investments | B11: 142000 | C11: Operating & reserve accounts
A12: Accounts Receivable & Other Assets | B12: 98400 | C12: Rent receivables + prepayments
A13: Total Assets at Fair Value | B13: =B10+B11+B12 -> 5920400
A14: Less: Borrowings | B14: -650000 | C14: KCB facility — 5-yr term
A15: Less: Other Liabilities | B15: -89500 | C15: Payables + accruals
A16: NET ASSET VALUE (NAV) | B16: =B13+B14+B15 -> 5180900 | C16: PRIMARY VALUATION OUTPUT
A17: Units in Issue ('000) | B17: 180541
A18: NAV per Unit (KES) | B18: =B16/B17*1000 -> 28696.529 | C18: ← KEY OUTPUT
A19: Current Market Price (KES) | B19: 6 | C19: NSE: FAHR
A20: Premium/(Discount) to NAV | B20: =(B19-B18)/B18 -> -0.99979092 | C20: (Market Price - NAV/Unit)/NAV/Unit
A22: B. CAPITALISATION RATE SENSITIVITY — IMPLIED PROPERTY VALUE
A23: Cap Rate applied to NOI: Value = NOI / Cap Rate
A24: Cap Rate | B24: Implied Portfolio Value (KES '000) | C24: Implied NAV/Unit (KES)
A25: 5.5% | B25: 5908618 | C25: 29962.82
A26: 6.0% | B26: 5416233 | C26: 27235.55
A27: 6.5% | B27: 4999600 | C27: 24927.86
A28: 7.0% | B28: 4642486 | C28: 22949.83
A29: 7.5% | B29: 4332987 | C29: 21235.55
A30: 8.0% | B30: 4062175 | C30: 19735.54
A31: 8.5% | B31: 3823224 | C31: 18412.01
A32: 9.0% | B32: 3610822 | C32: 17235.54

Sheet DDM Valuation
A1: DIVIDEND DISCOUNT MODEL (DDM) — GORDON GROWTH MODEL
A2: P = DPU₁ / (r - g) | REITs distribute ≥80% of income — DDM is a core valuation method
A4: A. GORDON GROWTH MODEL INPUTS
A5: Input | B5: Value | C5: Source | D5: Sensitivity Range
A6: DPU FY2024 (KES per unit) | B6: 1.25 | C6: Actual paid
A7: DPU Growth Year 1 (g₁) | B7: 0.04 | C7: Rental growth assumption
A8: DPU Growth Year 2 (g₂) | B8: 0.04
A9: DPU Growth Year 3 (g₃) | B9: 0.04
A10: DPU Growth Year 4 (g₄) | B10: 0.04
A11: DPU Growth Year 5 (g₅) | B11: 0.04
A12: Terminal Growth Rate (g_t) | B12: 0.04 | C12: Long-run rental + inflation
A13: Required Return on Equity (r) | B13: =Assumptions!B23 -> 0.1495 | C13: =B13 -> 0.1495
A14: WACC | B14: =Assumptions!B26 -> 0.147764 | C14: From Assumptions sheet
A15: DDM Discount Rate Used | B15: 0.15 | C15: Required equity return ← KEY
A17: B. MULTI-STAGE DDM (5-YEAR EXPLICIT + TERMINAL)
A18: Year | B18: DPU (KES) | C18: PV Factor | D18: PV of DPU (KES)
A19: Year 1 (FY2025E) | B19: =B6*(1+B7) -> 1.3 | C19: =1/(1+B15)^1 -> 0.86956522 | D19: =B19*C19 -> 1.1304348
A20: Year 2 (FY2026E) | B20: =B19*(1+B8) -> 1.352 | C20: =1/(1+B15)^2 -> 0.75614367 | D20: =B20*C20 -> 1.0223062
A21: Year 3 (FY2027E) | B21: =B20*(1+B9) -> 1.40608 | C21: =1/(1+B15)^3 -> 0.65751623 | D21: =B21*C21 -> 0.92452042
A22: Year 4 (FY2028E) | B22: =B21*(1+B10) -> 1.4623232 | C22: =1/(1+B15)^4 -> 0.57175325 | D22: =B22*C22 -> 0.83608804
A23: Year 5 (FY2029E) | B23: =B22*(1+B11) -> 1.5208161 | C23: =1/(1+B15)^5 -> 0.49717674 | D23: =B23*C23 -> 0.7561144
A24: Sum of PV (Year 1–5) | D24: =SUM(D19:D23) -> 4.6694639
A25: Terminal DPU (Year 5 × (1+g_t)) | B25: =B23*(1+B12) -> 1.5816488
A26: Terminal Value = Term DPU / (r - g_t) | B26: =B25/(B15-B12) -> 14.378625
A27: PV of Terminal Value | B27: =B26/(1+B15)^5 -> 7.1487179
A29: DDM FAIR VALUE PER UNIT (KES) | B29: =D24+B27 -> 11.818182
A30: Current Market Price (KES) | B30: =Assumptions!B31 -> 6
A31: Upside / (Downside) to DDM Value | B31: =(B29-B30)/B30 -> 0.96969697
A33: C. SIMPLE GORDON GROWTH: P = DPU₁/(r-g)
A34: Forward DPU (DPU₀ × (1+g)) | B34: =B6*(1+B7) -> 1.3
A35: Gordon GGM Value = DPU₁/(r-g) | B35: =B34/(B15-B12) -> 11.818182
A36: Premium/(Discount) to Market | B36: =(B35-6)/6 -> 0.96969697
A38: D. DPU vs REQUIRED YIELD — GORDON GROWTH SENSITIVITY (KES per unit)
A39: DPU ↓ / Yield → | B39: 8% | C39: 9% | D39: 10% | E39: 11% | F39: 12% | G39: 13% | H39: 15% | I39: 18%
A40: KES 1.00 | B40: 26 | C40: 20.8 | D40: 17.33 | E40: 14.86 | F40: 13 | G40: 11.56 | H40: 9.45 | I40: 7.43
A41: KES 1.10 | B41: 28.6 | C41: 22.88 | D41: 19.07 | E41: 16.34 | F41: 14.3 | G41: 12.71 | H41: 10.4 | I41: 8.17
A42: KES 1.20 | B42: 31.2 | C42: 24.96 | D42: 20.8 | E42: 17.83 | F42: 15.6 | G42: 13.87 | H42: 11.35 | I42: 8.91
A43: KES 1.25 | B43: 32.5 | C43: 26 | D43: 21.67 | E43: 18.57 | F43: 16.25 | G43: 14.44 | H43: 11.82 | I43: 9.29
A44: KES 1.30 | B44: 33.8 | C44: 27.04 | D44: 22.53 | E44: 19.31 | F44: 16.9 | G44: 15.02 | H44: 12.29 | I44: 9.66
A45: KES 1.40 | B45: 36.4 | C45: 29.12 | D45: 24.27 | E45: 20.8 | F45: 18.2 | G45: 16.18 | H45: 13.24 | I45: 10.4
...

Sheet DCF Valuation
A1: DCF VALUATION — FREE CASH FLOW TO EQUITY (FCFE)
A2: REIT FCFE = Distributable Income + D&A - Capex (maintenance) - ΔNWC
A4: PROJECTION ITEM | B4: FY2025E | C4: FY2026E | D4: FY2027E | E4: FY2028E | F4: FY2029E | G4: FY2030E (TV)
A5: INCOME PROJECTIONS
A6: Gross Rental Income | B6: 469374 | C6: =B6*(1+Assumptions!B11) -> 488148.96 | D6: =C6*(1+Assumptions!B11) -> 507674.92 | E6: =D6*(1+Assumptions!B11) -> 527981.92 | F6: =E6*(1+Assumptions!B11) -> 549101.19 | G6: =F6*(1+Assumptions!B11) -> 571065.24
A7: Other Income | B7: 8500 | C7: =B7 -> 8500 | D7: =C7 -> 8500 | E7: =D7 -> 8500 | F7: =E7 -> 8500 | G7: =F7 -> 8500
A8: Total Revenue | B8: 477874 | C8: =C6+C7 -> 496648.96 | D8: =D6+D7 -> 516174.92 | E8: =E6+E7 -> 536481.92 | F8: =F6+F7 -> 557601.19 | G8: =G6+G7 -> 579565.24
A9: Property Costs & Opex | B9: 152900 | C9: =B9*1.04 -> 159016 | D9: =C9*1.04 -> 165376.64 | E9: =D9*1.04 -> 171991.71 | F9: =E9*1.04 -> 178871.37 | G9: =F9*1.04 -> 186026.23
A10: Net Operating Income (NOI) | B10: 324974 | C10: =C8-C9 -> 337632.96 | D10: =D8-D9 -> 350798.28 | E10: =E8-E9 -> 364490.21 | F10: =F8-F9 -> 378729.82 | G10: =G8-G9 -> 393539.01
A11: Finance Costs | B11: 18600 | C11: =B11 -> 18600 | D11: =C11 -> 18600 | E11: =D11 -> 18600 | F11: =E11 -> 18600 | G11: =F11 -> 18600
A12: Distributable Income | B12: 306374 | C12: =C10-C11 -> 319032.96 | D12: =D10-D11 -> 332198.28 | E12: =E10-E11 -> 345890.21 | F12: =F10-F11 -> 360129.82 | G12: =G10-G11 -> 374939.01
A13: Add: Depreciation (non-cash) | B13: 8200 | C13: =B13 -> 8200 | D13: =C13 -> 8200 | E13: =D13 -> 8200 | F13: =E13 -> 8200 | G13: =F13 -> 8200
A14: Less: Maintenance Capex | B14: -12000 | C14: =B14*1.03 -> -12360 | D14: =C14*1.03 -> -12730.8 | E14: =D14*1.03 -> -13112.724 | F14: =E14*1.03 -> -13506.106 | G14: =F14*1.03 -> -13911.289
A15: FREE CASH FLOW TO EQUITY | B15: 302574 | C15: =C12+C13-C14 -> 339592.96 | D15: =D12+D13-D14 -> 353129.08 | E15: =E12+E13-E14 -> 367202.93 | F15: =F12+F13-F14 -> 381835.92 | G15: =G12+G13-G14 -> 397050.3
A17: DISCOUNTING & VALUATION
A18: Discount Period | B18: 1 | C18: 2 | D18: 3 | E18: 4 | F18: 5 | G18: 6
A19: Discount Factor (WACC) | B19: =1/(1+Assumptions!B26)^1 -> 0.87125925 | C19: =1/(1+Assumptions!B26)^2 -> 0.75909268 | D19: =1/(1+Assumptions!B26)^3 -> 0.66136652 | E19: =1/(1+Assumptions!B26)^4 -> 0.57622169 | F19: =1/(1+Assumptions!B26)^5 -> 0.50203848 | G19: =1/(1+Assumptions!B26)^6 -> 0.43740567
A20: PV of FCFE | B20: =B15*B19 -> 263620.4 | C20: =C15*C19 -> 257782.53 | D20: =D15*D19 -> 233547.75 | E20: =E15*E19 -> 211590.3 | F20: =F15*F19 -> 191696.33 | G20: =G15*G19 -> 173672.05
A22: TERMINAL VALUE & EQUITY BRIDGE
A23: Sum of PV FCFEs (Years 1–5) | B23: =SUM(B20:F20) -> 1158237.3
A24: Terminal Year FCFE (× (1+g)) | B24: =F15*(1+Assumptions!B12) -> 397109.36
A25: Terminal Value (Gordon Growth) | B25: =B24/(Assumptions!B26-Assumptions!B12) -> 3684990.9
A26: PV of Terminal Value | B26: =B25/(1+Assumptions!B26)^6 -> 1611835.9
A27: Total Equity Value (KES '000) | B27: =B23+B26+142000-650000 -> 2262073.2
A28: Units in Issue ('000) | B28: 180541
A29: DCF Fair Value per Unit (KES) | B29: =B27/B28*1000 -> 12529.416
A30: Current Market Price (KES) | B30: 6
A31: Upside / (Downside) | B31: =(B29-B30)/B30 -> 2087.2359

Sheet Cap Rate Analysis
A1: CAPITALISATION RATE ANALYSIS
A2: Cap Rate = NOI / Property Value | Fundamental pricing mechanism for income properties
A4: A. FAHARI I-REIT — CURRENT CAP RATE BREAKDOWN
A5: Metric | B5: Value | C5: Source | D5: Commentary
A6: Net Operating Income (NOI) | B6: 324974 | C6: FY2024 actual
A7: Portfolio Value (Fair Value) | B7: 5680000 | C7: CBRE external valuation
A8: In-Place Cap Rate (NOI/Value) | B8: 0.0572 | C8: Current yield on portfolio
A9: Gross Rental Yield | B9: 0.083 | C9: Before costs
A10: Net Yield (after finance) | B10: 0.0572 | C10: NOI/Portfolio Value
A11: Occupancy Drag (1-Occ) | B11: 0.188 | C11: 19% vacancy dragging yield
A12: Stabilised Cap Rate (at 90% occ) | B12: 0.0634 | C12: Full occupancy potential
A14: B. NAIROBI MARKET CAP RATE BENCHMARKS
A15: Property Type | B15: Market Cap Rate | C15: Sub-Market | D15: Commentary
A16: Grade A Retail (Westgate, Garden City) | B16: 7.5–8.5% | C16: Nairobi Westlands | D16: Prime malls; strong anchors
A17: Grade B Retail (Neighbourhood malls) | B17: 9.5–11.0% | C17: Nairobi suburbs | D17: Greenspan fits this bucket
A18: Grade A Office (Upper Hill, Westlands) | B18: 8.0–9.0% | C18: Upper Hill / Westlands | D18: Trophy offices
A19: Grade B Office (Kilimani, Gigiri) | B19: 10.0–12.0% | C19: Mid-tier locations | D19: 67 Gitanga Road fits here
A20: Industrial / Logistics | B20: 8.5–10.0% | C20: Mombasa Rd corridor
A21: Residential (upscale) | B21: 5.0–6.5% | C21: Karen, Muthaiga | D21: Karen property
A22: ILAM Fahari Portfolio (blended) | B22: 5.7% | C22: Mixed | D22: Blended in-place cap rate
A24: C. IMPLIED VALUE AT DIFFERENT CAP RATES (NOI = KES 324,974K)
A25: Cap Rate | B25: Implied Portfolio Value | C25: Implied NAV/Unit (KES) | D25: vs Current KES 6.00
A26: 5.0% | B26: 6499480 | C26: 33235.55 | D26: 5538.2589
A27: 5.5% | B27: 5908618 | C27: 29962.82 | D27: 4992.804
A28: 6.0% | B28: 5416233 | C28: 27235.55 | D28: 4538.2582
A29: 6.5% | B29: 4999600 | C29: 24927.86 | D29: 4153.6426
A30: 7.0% | B30: 4642486 | C30: 22949.83 | D30: 3823.9721
A31: 7.5% | B31: 4332987 | C31: 21235.55 | D31: 3538.2576
A32: 8.0% | B32: 4062175 | C32: 19735.54 | D32: 3288.2575
A33: 8.5% | B33: 3823224 | C33: 18412.01 | D33: 3067.6691
A34: 9.0% | B34: 3610822 | C34: 17235.54 | D34: 2871.5905
A35: 9.5% | B35: 3420779 | C35: 16182.91 | D35: 2696.1518
A36: 10.0% | B36: 3249740 | C36: 15235.54 | D36: 2538.257

Sheet Sensitivity Analysis
A1: SENSITIVITY ANALYSIS — ILAM FAHARI I-REIT
A2: Key sensitivities: cap rate, occupancy, DPU growth, required return
A4: TABLE 1: DDM FAIR VALUE (KES) — Required Return vs DPU Growth Rate
A5: Req.Return ↓ / DPU Gr → | B5: 2.0% | C5: 3.0% | D5: 4.0% | E5: 5.0% | F5: 6.0% | G5: 7.0% | H5: 8.0%
A6: 8% | B6: 21.25 | C6: 25.75 | D6: 32.5 | E6: 43.75 | F6: 66.25 | G6: 133.75 | H6: N/M
A7: 9% | B7: 18.21 | C7: 21.46 | D7: 26 | E7: 32.81 | F7: 44.17 | G7: 66.88 | H7: 135
A8: 10% | B8: 15.94 | C8: 18.39 | D8: 21.67 | E8: 26.25 | F8: 33.12 | G8: 44.58 | H8: 67.5
A9: 11% | B9: 14.17 | C9: 16.09 | D9: 18.57 | E9: 21.88 | F9: 26.5 | G9: 33.44 | H9: 45
A10: 12% | B10: 12.75 | C10: 14.31 | D10: 16.25 | E10: 18.75 | F10: 22.08 | G10: 26.75 | H10: 33.75
A11: 13% | B11: 11.59 | C11: 12.88 | D11: 14.44 | E11: 16.41 | F11: 18.93 | G11: 22.29 | H11: 27
A12: 15% | B12: 9.81 | C12: 10.73 | D12: 11.82 | E12: 13.13 | F12: 14.72 | G12: 16.72 | H12: 19.29
A13: 18% | B13: 7.97 | C13: 8.58 | D13: 9.29 | E13: 10.1 | F13: 11.04 | G13: 12.16 | H13: 13.5
A16: TABLE 2: NAV PER UNIT (KES) — Cap Rate vs Occupancy Rate
A17: Cap Rate ↓ / Occ → | B17: 70% | C17: 75% | D17: 80% | E17: 85% | F17: 90% | G17: 92% | H17: 95%
A18: 5.5% | B18: 25448.71 | C18: 27463.94 | D18: 29479.17 | E18: 31494.4 | F18: 33509.62 | G18: 34315.72 | H18: 35524.85
A19: 6.0% | B19: 23097.62 | C19: 24944.91 | D19: 26792.2 | E19: 28639.49 | F19: 30486.78 | G19: 31225.7 | H19: 32334.07
A20: 6.5% | B20: 21108.22 | C20: 22813.42 | D20: 24518.61 | E20: 26223.8 | F20: 27928.99 | G20: 28611.07 | H20: 29634.19
A21: 7.0% | B21: 19403.03 | C21: 20986.43 | D21: 22569.82 | E21: 24153.21 | F21: 25736.6 | G21: 26369.96 | H21: 27320
A22: 7.5% | B22: 17925.2 | C22: 19403.03 | D22: 20880.87 | E22: 22358.7 | F22: 23836.53 | G22: 24427.67 | H22: 25314.37
A23: 8.0% | B23: 16632.09 | C23: 18017.56 | D23: 19403.03 | E23: 20788.5 | F23: 22173.97 | G23: 22728.16 | H23: 23559.44
A24: 8.5% | B24: 15491.12 | C24: 16795.09 | D24: 18099.06 | E24: 19403.03 | F24: 20707 | G24: 21228.59 | H24: 22010.97
A25: 9.0% | B25: 14476.92 | C25: 15708.45 | D25: 16939.98 | E25: 18171.5 | F25: 19403.03 | G25: 19895.64 | H25: 20634.56
A28: TABLE 3: DPU (KES) vs REQUIRED YIELD — GORDON GROWTH FAIR VALUE
A29: DPU ↓ / Req Yield → | B29: 6% | C29: 7% | D29: 8% | E29: 9% | F29: 10% | G29: 12% | H29: 15%
A30: KES 0.80 | B30: 41.6 | C30: 27.73 | D30: 20.8 | E30: 16.64 | F30: 13.87 | G30: 10.4 | H30: 7.56
A31: KES 0.90 | B31: 46.8 | C31: 31.2 | D31: 23.4 | E31: 18.72 | F31: 15.6 | G31: 11.7 | H31: 8.51
A32: KES 1.00 | B32: 52 | C32: 34.67 | D32: 26 | E32: 20.8 | F32: 17.33 | G32: 13 | H32: 9.45
A33: KES 1.10 | B33: 57.2 | C33: 38.13 | D33: 28.6 | E33: 22.88 | F33: 19.07 | G33: 14.3 | H33: 10.4
A34: KES 1.20 | B34: 62.4 | C34: 41.6 | D34: 31.2 | E34: 24.96 | F34: 20.8 | G34: 15.6 | H34: 11.35
A35: KES 1.25 | B35: 65 | C35: 43.33 | D35: 32.5 | E35: 26 | F35: 21.67 | G35: 16.25 | H35: 11.82
A36: KES 1.30 | B36: 67.6 | C36: 45.07 | D36: 33.8 | E36: 27.04 | F36: 22.53 | G36: 16.9 | H36: 12.29
A37: KES 1.50 | B37: 78 | C37: 52 | D37: 39 | E37: 31.2 | F37: 26 | G37: 19.5 | H37: 14.18

Sheet Summary
A1: INVESTMENT SUMMARY — ILAM FAHARI I-REIT
A2: REIT Valuation Synthesis | Recommendation | Investment Thesis
A4: VALUATION SUMMARY BRIDGE
A5: Method | B5: Fair Value / Unit (KES) | C5: Weight | D5: Commentary
A6: NAV per Unit (Direct Valuation) | B6: 28.69 | C6: 0.4 | D6: Primary metric — asset-backed floor value
A7: Cap Rate Implied (at 8.0% market rate) | B7: 23286.54 | C7: 0.25 | D7: Market-rate normalised value
A8: DDM — Gordon Growth (r=15%) | B8: 11.82 | C8: 0.2 | D8: Required yield approach
A9: DCF (FCFE, WACC=14%) | B9: 7128.44 | C9: 0.15 | D9: Conservative FCF approach
A10: WEIGHTED AVERAGE FAIR VALUE (KES) | B10: =SUMPRODUCT(B6:B9,C6:C9)/SUM(C6:C9) -> 6904.741
A12: CURRENT MARKET vs FAIR VALUE
A13: Current Market Price (NSE: FAHR) | B13: 6
A14: Weighted Average Fair Value | B14: =B10 -> 6904.741
A15: NAV per Unit (Book Value) | B15: 28.69
A16: Premium/(Discount) to WAV | B16: =(B12-6)/6 -> -1
A17: Premium/(Discount) to NAV | B17: =(6-28.69)/28.69 -> -0.7908679
A19: INVESTMENT RECOMMENDATION
A20: Rating | B20: BUY
A21: Primary Catalyst | B21: Occupancy recovery → NOI growth → NAV re-rating
A23: INVESTMENT THESIS
A24: 79% discount to NAV
A25: The stock trades at KES 6.00 vs NAV of KES 28.69 — a 79.1% discount. For an income REIT holding tangible, valued properties, this is the defining mispricing. The discount implies either the market prices in fire-sale asset disposals or sustained income deterioration — neither of which is supported by the current portfolio operations.
A26: 18.5% DPU yield at current price
A27: At KES 6.00/unit with DPU of KES 1.25, the dividend yield is 20.8%. Even after stress-testing occupancy lower and applying a 10% market cap rate (distressed), the DDM fair value exceeds KES 13 — more than double current price.
A28: Occupancy recovery is the lever
A29: Current occupancy of 81.2% compares unfavorably to regional REIT benchmarks of 90%+. Each 1% occupancy gain adds ~KES 4.7mn to annual NOI. A recovery to 90% increases NOI by ~KES 42mn (+13%) — a clear earnings catalyst.
A30: Anchor-tenant risk is manageable
A31: Greenspan Mall (the primary asset) benefits from Naivas Supermarket and local retail anchors. The WAULT of 3.2 years creates re-leasing risk but also upside from above-inflation rent reviews in a recovering Nairobi retail market.
A32: Primary risk: NSE REIT liquidity
A33: FAHR suffers from extremely thin liquidity on the NSE — daily traded volumes are often below KES 500K. This illiquidity discount is real and structural, limiting the investor base to long-term holders willing to weather mark-to-market volatility.
